/software/python-anaconda-2020.11-el8-x86_64/lib/python3.8/site-packages/torch/cuda/__init__.py:143: UserWarning: 
NVIDIA A100-PCIE-40GB with CUDA capability sm_80 is not compatible with the current PyTorch installation.
The current PyTorch install supports CUDA capabilities sm_37 sm_50 sm_60 sm_70.
If you want to use the NVIDIA A100-PCIE-40GB GPU with PyTorch, please check the instructions at https://pytorch.org/get-started/locally/

  warnings.warn(incompatible_device_warn.format(device_name, capability, " ".join(arch_list), device_name))
Traceback (most recent call last):
  File "exp1.py", line 122, in <module>
    train_model_with_generator(model=model,
  File "exp1.py", line 98, in train_model_with_generator
    train_loss = train_epoch_with_generator(model, optimizer, generator, batch_size, iter_per_epoch, bceloss, subset)
  File "exp1.py", line 75, in train_epoch_with_generator
    loss = model.get_mseloss(Y, beta)
  File "exp1.py", line 53, in get_mseloss
    output = self.forward(data)
  File "exp1.py", line 45, in forward
    u = self.relu(self.fc1(input))
  File "/software/python-anaconda-2020.11-el8-x86_64/lib/python3.8/site-packages/torch/nn/modules/module.py", line 1102, in _call_impl
    return forward_call(*input, **kwargs)
  File "/software/python-anaconda-2020.11-el8-x86_64/lib/python3.8/site-packages/torch/nn/modules/linear.py", line 103, in forward
    return F.linear(input, self.weight, self.bias)
  File "/software/python-anaconda-2020.11-el8-x86_64/lib/python3.8/site-packages/torch/nn/functional.py", line 1848, in linear
    return torch._C._nn.linear(input, weight, bias)
RuntimeError: CUDA error: no kernel image is available for execution on the device
CUDA kernel errors might be asynchronously reported at some other API call,so the stacktrace below might be incorrect.
For debugging consider passing CUDA_LAUNCH_BLOCKING=1.
